Workbook

Sheet CSVex
A1: item_name | B1: unit_type | C1: unit_price | D1: is_active | E1: sort_order
A2: =IF(加工用!A3="","",加工用!A3) -> 要件定義/打ち合わせ | B2: =IF(加工用!B3="","",加工用!B3) -> person_month | C2: =IF(加工用!C3="","",加工用!C3) -> 1200000 | D2: =IF(加工用!D3="","",加工用!D3) -> 1 | E2: =IF(加工用!E3="","",加工用!E3) -> 100
A3: =IF(加工用!A4="","",加工用!A4) -> 基本設計 | B3: =IF(加工用!B4="","",加工用!B4) -> person_month | C3: =IF(加工用!C4="","",加工用!C4) -> 1000000 | D3: =IF(加工用!D4="","",加工用!D4) -> 1 | E3: =IF(加工用!E4="","",加工用!E4) -> 100
A4: =IF(加工用!A5="","",加工用!A5) -> 情報設計 | B4: =IF(加工用!B5="","",加工用!B5) -> person_month | C4: =IF(加工用!C5="","",加工用!C5) -> 1000000 | D4: =IF(加工用!D5="","",加工用!D5) -> 1 | E4: =IF(加工用!E5="","",加工用!E5) -> 100
A5: =IF(加工用!A6="","",加工用!A6) -> 外部連携設計 | B5: =IF(加工用!B6="","",加工用!B6) -> person_month | C5: =IF(加工用!C6="","",加工用!C6) -> 1000000 | D5: =IF(加工用!D6="","",加工用!D6) -> 1 | E5: =IF(加工用!E6="","",加工用!E6) -> 100
A6: =IF(加工用!A7="","",加工用!A7) -> テスト設計 | B6: =IF(加工用!B7="","",加工用!B7) -> person_month | C6: =IF(加工用!C7="","",加工用!C7) -> 1000000 | D6: =IF(加工用!D7="","",加工用!D7) -> 1 | E6: =IF(加工用!E7="","",加工用!E7) -> 100
A7: =IF(加工用!A8="","",加工用!A8) -> ワイヤーフレーム作成 | B7: =IF(加工用!B8="","",加工用!B8) -> person_month | C7: =IF(加工用!C8="","",加工用!C8) -> 1000000 | D7: =IF(加工用!D8="","",加工用!D8) -> 1 | E7: =IF(加工用!E8="","",加工用!E8) -> 100
A8: =IF(加工用!A9="","",加工用!A9) -> SEO設計 | B8: =IF(加工用!B9="","",加工用!B9) -> person_month | C8: =IF(加工用!C9="","",加工用!C9) -> 1000000 | D8: =IF(加工用!D9="","",加工用!D9) -> 1 | E8: =IF(加工用!E9="","",加工用!E9) -> 100
A9: =IF(加工用!A10="","",加工用!A10) -> 基本デザイン | B9: =IF(加工用!B10="","",加工用!B10) -> set | C9: =IF(加工用!C10="","",加工用!C10) -> 200000 | D9: =IF(加工用!D10="","",加工用!D10) -> 1 | E9: =IF(加工用!E10="","",加工用!E10) -> 200
A10: =IF(加工用!A11="","",加工用!A11) -> 動的ページデザイン | B10: =IF(加工用!B11="","",加工用!B11) -> page | C10: =IF(加工用!C11="","",加工用!C11) -> 30000 | D10: =IF(加工用!D11="","",加工用!D11) -> 1 | E10: =IF(加工用!E11="","",加工用!E11) -> 200
A11: =IF(加工用!A12="","",加工用!A12) -> 静的ページデザイン | B11: =IF(加工用!B12="","",加工用!B12) -> page | C11: =IF(加工用!C12="","",加工用!C12) -> 10000 | D11: =IF(加工用!D12="","",加工用!D12) -> 1 | E11: =IF(加工用!E12="","",加工用!E12) -> 200
A12: =IF(加工用!A13="","",加工用!A13) -> LPデザイン | B12: =IF(加工用!B13="","",加工用!B13) -> set | C12: =IF(加工用!C13="","",加工用!C13) -> 200000 | D12: =IF(加工用!D13="","",加工用!D13) -> 1 | E12: =IF(加工用!E13="","",加工用!E13) -> 200
A13: =IF(加工用!A14="","",加工用!A14) -> 他社デザインpsd起こし | B13: =IF(加工用!B14="","",加工用!B14) -> page | C13: =IF(加工用!C14="","",加工用!C14) -> 10000 | D13: =IF(加工用!D14="","",加工用!D14) -> 1 | E13: =IF(加工用!E14="","",加工用!E14) -> 200
... A21: =IF(加工用!A22="","",加工用!A22) -> リキッドレイアウト | B21: =IF(加工用!B22="","",加工用!B22) -> set | C21: =IF(加工用!C22="","",加工用!C22) | D21: =IF(加工用!D22="","",加工用!D22) -> 1 | E21: =IF(加工用!E22="","",加工用!E22) -> 200
A22: =IF(加工用!A35="","",加工用!A35) -> ディレクション費用 | B22: =IF(加工用!B35="","",加工用!B35) -> set | C22: =IF(加工用!C35="","",加工用!C35) -> 100000 | D22: =IF(加工用!D35="","",加工用!D35) -> 1 | E22: =IF(加工用!E35="","",加工用!E35) -> 300
A23: =IF(加工用!A23="","",加工用!A23) -> 公開側テンプレート化 | B23: =IF(加工用!B23="","",加工用!B23) -> person_month | C23: =IF(加工用!C23="","",加工用!C23) -> 1000000 | D23: =IF(加工用!D23="","",加工用!D23) -> 1 | E23: =IF(加工用!E23="","",加工用!E23) -> 300
A24: =IF(加工用!A24="","",加工用!A24) -> 公開側プログラミング | B24: =IF(加工用!B24="","",加工用!B24) -> person_month | C24: =IF(加工用!C24="","",加工用!C24) -> 1000000 | D24: =IF(加工用!D24="","",加工用!D24) -> 1 | E24: =IF(加工用!E24="","",加工用!E24) -> 300
A25: =IF(加工用!A25="","",加工用!A25) -> 管理側プログラミング | B25: =IF(加工用!B25="","",加工用!B25) -> person_month | C25: =IF(加工用!C25="","",加工用!C25) -> 1000000 | D25: =IF(加工用!D25="","",加工用!D25) -> 1 | E25: =IF(加工用!E25="","",加工用!E25) -> 300
A26: =IF(加工用!A26="","",加工用!A26) -> 結合テスト | B26: =IF(加工用!B26="","",加工用!B26) -> person_month | C26: =IF(加工用!C26="","",加工用!C26) -> 800000 | D26: =IF(加工用!D26="","",加工用!D26) -> 1 | E26: =IF(加工用!E26="","",加工用!E26) -> 300
A27: =IF(加工用!A27="","",加工用!A27) -> 外部連携テスト | B27: =IF(加工用!B27="","",加工用!B27) -> person_month | C27: =IF(加工用!C27="","",加工用!C27) -> 800000 | D27: =IF(加工用!D27="","",加工用!D27) -> 1 | E27: =IF(加工用!E27="","",加工用!E27) -> 300
A28: =IF(加工用!A28="","",加工用!A28) -> ブラウザテスト | B28: =IF(加工用!B28="","",加工用!B28) -> person_month | C28: =IF(加工用!C28="","",加工用!C28) -> 800000 | D28: =IF(加工用!D28="","",加工用!D28) -> 1 | E28: =IF(加工用!E28="","",加工用!E28) -> 300
A29: =IF(加工用!A29="","",加工用!A29) -> 脆弱性診断（レポートなし） | B29: =IF(加工用!B29="","",加工用!B29) -> times | C29: =IF(加工用!C29="","",加工用!C29) -> 50000 | D29: =IF(加工用!D29="","",加工用!D29) -> 1 | E29: =IF(加工用!E29="","",加工用!E29) -> 300
A30: =IF(加工用!A30="","",加工用!A30) -> 脆弱性診断（レポートあり） | B30: =IF(加工用!B30="","",加工用!B30) -> times | C30: =IF(加工用!C30="","",加工用!C30) -> 80000 | D30: =IF(加工用!D30="","",加工用!D30) -> 1 | E30: =IF(加工用!E30="","",加工用!E30) -> 300
A31: =IF(加工用!A31="","",加工用!A31) -> 操作レクチャー | B31: =IF(加工用!B31="","",加工用!B31) -> times | C31: =IF(加工用!C31="","",加工用!C31) -> 50000 | D31: =IF(加工用!D31="","",加工用!D31) -> 1 | E31: =IF(加工用!E31="","",加工用!E31) -> 300
A32: =IF(加工用!A32="","",加工用!A32) -> CMS操作マニュアル【Mini】 | B32: =IF(加工用!B32="","",加工用!B32) -> set | C32: =IF(加工用!C32="","",加工用!C32) -> 50000 | D32: =IF(加工用!D32="","",加工用!D32) -> 1 | E32: =IF(加工用!E32="","",加工用!E32) -> 300
A33: =IF(加工用!A33="","",加工用!A33) -> CMS操作マニュアル【Standard】 | B33: =IF(加工用!B33="","",加工用!B33) -> set | C33: =IF(加工用!C33="","",加工用!C33) -> 100000 | D33: =IF(加工用!D33="","",加工用!D33) -> 1 | E33: =IF(加工用!E33="","",加工用!E33) -> 300
A34: =IF(加工用!A34="","",加工用!A34) -> リリース作業 | B34: =IF(加工用!B34="","",加工用!B34) -> set | C34: =IF(加工用!C34="","",加工用!C34) -> 100000 | D34: =IF(加工用!D34="","",加工用!D34) -> 1 | E34: =IF(加工用!E34="","",加工用!E34) -> 300
A35: =IF(加工用!A36="","",加工用!A36) -> 進行管理費 | B35: =IF(加工用!B36="","",加工用!B36) -> percent | C35: =IF(加工用!C36="","",加工用!C36) -> 10 | D35: =IF(加工用!D36="","",加工用!D36) -> 1 | E35: =IF(加工用!E36="","",加工用!E36) -> 300
A36: =IF(加工用!A37="","",加工用!A37) -> 会員機能 | B36: =IF(加工用!B37="","",加工用!B37) -> set | C36: =IF(加工用!C37="","",加工用!C37) -> 200000 | D36: =IF(加工用!D37="","",加工用!D37) -> 1 | E36: =IF(加工用!E37="","",加工用!E37) -> 400
A37: =IF(加工用!A38="","",加工用!A38) -> お問合せフォーム（Mail） | B37: =IF(加工用!B38="","",加工用!B38) -> set | C37: =IF(加工用!C38="","",加工用!C38) -> 70000 | D37: =IF(加工用!D38="","",加工用!D38) -> 1 | E37: =IF(加工用!E38="","",加工用!E38) -> 400
A38: =IF(加工用!A39="","",加工用!A39) -> お問合せフォーム（Mail＋DB） | B38: =IF(加工用!B39="","",加工用!B39) -> set | C38: =IF(加工用!C39="","",加工用!C39) -> 100000 | D38: =IF(加工用!D39="","",加工用!D39) -> 1 | E38: =IF(加工用!E39="","",加工用!E39) -> 400
A39: =IF(加工用!A40="","",加工用!A40) -> お問合せフォーム（Formプラグイン） | B39: =IF(加工用!B40="","",加工用!B40) -> set | C39: =IF(加工用!C40="","",加工用!C40) -> 50000 | D39: =IF(加工用!D40="","",加工用!D40) -> 1 | E39: =IF(加工用!E40="","",加工用!E40) -> 400
A40: =IF(加工用!A41="","",加工用!A41) -> SITEMANAGE Mini | B40: =IF(加工用!B41="","",加工用!B41) -> set | C40: =IF(加工用!C41="","",加工用!C41) -> 300000 | D40: =IF(加工用!D41="","",加工用!D41) -> 1 | E40: =IF(加工用!E41="","",加工用!E41) -> 50
A41: =IF(加工用!A42="","",加工用!A42) -> SITEMANAGE Standard | B41: =IF(加工用!B42="","",加工用!B42) -> set | C41: =IF(加工用!C42="","",加工用!C42) -> 1000000 | D41: =IF(加工用!D42="","",加工用!D42) -> 1 | E41: =IF(加工用!E42="","",加工用!E42) -> 50
A42: =IF(加工用!A43="","",加工用!A43) -> Site | B42: =IF(加工用!B43="","",加工用!B43) -> set | C42: =IF(加工用!C43="","",加工用!C43) | D42: =IF(加工用!D43="","",加工用!D43) -> 1 | E42: =IF(加工用!E43="","",加工用!E43) -> 50
A43: =IF(加工用!A44="","",加工用!A44) -> Staff | B43: =IF(加工用!B44="","",加工用!B44) -> set | C43: =IF(加工用!C44="","",加工用!C44) | D43: =IF(加工用!D44="","",加工用!D44) -> 1 | E43: =IF(加工用!E44="","",加工用!E44) -> 50
A44: =IF(加工用!A45="","",加工用!A45) -> Parts | B44: =IF(加工用!B45="","",加工用!B45) -> set | C44: =IF(加工用!C45="","",加工用!C45) -> 100000 | D44: =IF(加工用!D45="","",加工用!D45) -> 1 | E44: =IF(加工用!E45="","",加工用!E45) -> 50
A45: =IF(加工用!A46="","",加工用!A46) -> Page | B45: =IF(加工用!B46="","",加工用!B46) -> set | C45: =IF(加工用!C46="","",加工用!C46) -> 100000 | D45: =IF(加工用!D46="","",加工用!D46) -> 1 | E45: =IF(加工用!E46="","",加工用!E46) -> 50
A46: =IF(加工用!A47="","",加工用!A47) -> Contents | B46: =IF(加工用!B47="","",加工用!B47) -> set | C46: =IF(加工用!C47="","",加工用!C47) -> 100000 | D46: =IF(加工用!D47="","",加工用!D47) -> 1 | E46: =IF(加工用!E47="","",加工用!E47) -> 50
... A150: =IF(加工用!A151="","",加工用!A151) -> Googleマーチャントセンター連携 | B150: =IF(加工用!B151="","",加工用!B151) -> set | C150: =IF(加工用!C151="","",加工用!C151) -> 200000 | D150: =IF(加工用!D151="","",加工用!D151) -> 1 | E150: =IF(加工用!E151="","",加工用!E151) -> 500

Sheet 加工用
A1: item_name | B1: unit_type | C1: unit_price | D1: is_active | E1: sort_order
A2: 項目名 | B2: 単位 | C2: 単価 | D2: 1表示 0非表示 | E2: 並び順（昇順） | F2: 入力補助
A3: 要件定義/打ち合わせ | B3: =VLOOKUP(F3,単位マスタ!$A:$B,2,0) -> person_month | C3: 1200000 | D3: 1 | E3: 100 | F3: 人月
A4: 基本設計 | B4: =VLOOKUP(F4,単位マスタ!$A:$B,2,0) -> person_month | C4: 1000000 | D4: 1 | E4: 100 | F4: 人月
A5: 情報設計 | B5: =VLOOKUP(F5,単位マスタ!$A:$B,2,0) -> person_month | C5: 1000000 | D5: 1 | E5: 100 | F5: 人月
A6: 外部連携設計 | B6: =VLOOKUP(F6,単位マスタ!$A:$B,2,0) -> person_month | C6: 1000000 | D6: 1 | E6: 100 | F6: 人月
A7: テスト設計 | B7: =VLOOKUP(F7,単位マスタ!$A:$B,2,0) -> person_month | C7: 1000000 | D7: 1 | E7: 100 | F7: 人月
A8: ワイヤーフレーム作成 | B8: =VLOOKUP(F8,単位マスタ!$A:$B,2,0) -> person_month | C8: 1000000 | D8: 1 | E8: 100 | F8: 人月
A9: SEO設計 | B9: =VLOOKUP(F9,単位マスタ!$A:$B,2,0) -> person_month | C9: 1000000 | D9: 1 | E9: 100 | F9: 人月
A10: 基本デザイン | B10: =VLOOKUP(F10,単位マスタ!$A:$B,2,0) -> set | C10: 200000 | D10: 1 | E10: 200 | F10: 式
A11: 動的ページデザイン | B11: =VLOOKUP(F11,単位マスタ!$A:$B,2,0) -> page | C11: 30000 | D11: 1 | E11: 200 | F11: 頁
A12: 静的ページデザイン | B12: =VLOOKUP(F12,単位マスタ!$A:$B,2,0) -> page | C12: 10000 | D12: 1 | E12: 200 | F12: 頁
A13: LPデザイン | B13: =VLOOKUP(F13,単位マスタ!$A:$B,2,0) -> set | C13: 200000 | D13: 1 | E13: 200 | F13: 式
A14: 他社デザインpsd起こし | B14: =VLOOKUP(F14,単位マスタ!$A:$B,2,0) -> page | C14: 10000 | D14: 1 | E14: 200 | F14: 頁
... A19: LPコーディング | B19: =VLOOKUP(F19,単位マスタ!$A:$B,2,0) -> set | C19: 200000 | D19: 1 | E19: 200 | F19: 式
A20: 他社デザインページコーディング | B20: =VLOOKUP(F20,単位マスタ!$A:$B,2,0) -> set | D20: 1 | E20: 200 | F20: 式
A21: レスポンシブ対応 | B21: =VLOOKUP(F21,単位マスタ!$A:$B,2,0) -> set | D21: 1 | E21: 200 | F21: 式
A22: リキッドレイアウト | B22: =VLOOKUP(F22,単位マスタ!$A:$B,2,0) -> set | D22: 1 | E22: 200 | F22: 式
A23: 公開側テンプレート化 | B23: =VLOOKUP(F23,単位マスタ!$A:$B,2,0) -> person_month | C23: 1000000 | D23: 1 | E23: 300 | F23: 人月
A24: 公開側プログラミング | B24: =VLOOKUP(F24,単位マスタ!$A:$B,2,0) -> person_month | C24: 1000000 | D24: 1 | E24: 300 | F24: 人月
A25: 管理側プログラミング | B25: =VLOOKUP(F25,単位マスタ!$A:$B,2,0) -> person_month | C25: 1000000 | D25: 1 | E25: 300 | F25: 人月
A26: 結合テスト | B26: =VLOOKUP(F26,単位マスタ!$A:$B,2,0) -> person_month | C26: 800000 | D26: 1 | E26: 300 | F26: 人月
A27: 外部連携テスト | B27: =VLOOKUP(F27,単位マスタ!$A:$B,2,0) -> person_month | C27: 800000 | D27: 1 | E27: 300 | F27: 人月
A28: ブラウザテスト | B28: =VLOOKUP(F28,単位マスタ!$A:$B,2,0) -> person_month | C28: 800000 | D28: 1 | E28: 300 | F28: 人月
A29: 脆弱性診断（レポートなし） | B29: =VLOOKUP(F29,単位マスタ!$A:$B,2,0) -> times | C29: 50000 | D29: 1 | E29: 300 | F29: 回
A30: 脆弱性診断（レポートあり） | B30: =VLOOKUP(F30,単位マスタ!$A:$B,2,0) -> times | C30: 80000 | D30: 1 | E30: 300 | F30: 回
A31: 操作レクチャー | B31: =VLOOKUP(F31,単位マスタ!$A:$B,2,0) -> times | C31: 50000 | D31: 1 | E31: 300 | F31: 回
A32: CMS操作マニュアル【Mini】 | B32: =VLOOKUP(F32,単位マスタ!$A:$B,2,0) -> set | C32: 50000 | D32: 1 | E32: 300 | F32: 式
A33: CMS操作マニュアル【Standard】 | B33: =VLOOKUP(F33,単位マスタ!$A:$B,2,0) -> set | C33: 100000 | D33: 1 | E33: 300 | F33: 式
A34: リリース作業 | B34: =VLOOKUP(F34,単位マスタ!$A:$B,2,0) -> set | C34: 100000 | D34: 1 | E34: 300 | F34: 式
... A42: SITEMANAGE Standard | B42: =VLOOKUP(F42,単位マスタ!$A:$B,2,0) -> set | C42: 1000000 | D42: 1 | E42: 50 | F42: 式
A43: Site | B43: =VLOOKUP(F43,単位マスタ!$A:$B,2,0) -> set | D43: 1 | E43: 50 | F43: 式
A44: Staff | B44: =VLOOKUP(F44,単位マスタ!$A:$B,2,0) -> set | D44: 1 | E44: 50 | F44: 式
A45: Parts | B45: =VLOOKUP(F45,単位マスタ!$A:$B,2,0) -> set | C45: 100000 | D45: 1 | E45: 50 | F45: 式
A46: Page | B46: =VLOOKUP(F46,単位マスタ!$A:$B,2,0) -> set | C46: 100000 | D46: 1 | E46: 50 | F46: 式
A47: Contents | B47: =VLOOKUP(F47,単位マスタ!$A:$B,2,0) -> set | C47: 100000 | D47: 1 | E47: 50 | F47: 式
A48: Banner | B48: =VLOOKUP(F48,単位マスタ!$A:$B,2,0) -> set | C48: 100000 | D48: 1 | E48: 50 | F48: 式
A49: Form | B49: =VLOOKUP(F49,単位マスタ!$A:$B,2,0) -> set | C49: 300000 | D49: 1 | E49: 50 | F49: 式
A50: SiteReport | B50: =VLOOKUP(F50,単位マスタ!$A:$B,2,0) -> set | C50: 100000 | D50: 1 | E50: 50 | F50: 式
A51: MailTemplate | B51: =VLOOKUP(F51,単位マスタ!$A:$B,2,0) -> set | C51: 100000 | D51: 1 | E51: 50 | F51: 式
...

Sheet プラグイン一覧
A1: 名前 | C1: 価格
A2: SITEMANAGE Mini | C2: 300000
A3: SITEMANAGE Standard | C3: 1000000
A4: Site
A5: Staff
A6: Parts | C6: 100000
A7: Page | C7: 100000
A8: Contents | C8: 100000
A9: Banner | C9: 100000
A10: Form | C10: 300000
A11: SiteReport | C11: 100000
A12: MailTemplate | C12: 100000
A13: Category | C13: 50000
A14: Approval | C14: 200000
A15: Tag | C15: 50000
A16: Client | C16: 100000
A17: Corporate | C17: 100000
... A79: Webp | C79: 100000
A80: BasicAuth
A81: ImageAuthentication | C81: 50000
A82: IPRestrict
A83: NGWordChecker | C83: 100000
A84: TwoAuth | C84: 50000
A85: reCAPTCHA | C85: 100000
A86: Facebook
A87: Post FB Update | C87: 200000
A88: X
A89: Post X | C89: 100000
A90: Post Youtube | C90: 200000
A91: SocialBookmark
A92: SSO | C92: 200000
A93: CSVインポート | C93: 200000
A94: CSVエクスポート | C94: 50000
A95: カスタムエクスポート | C95: 100000
A96: オリジナルエクスポート | C96: 200000
A97: 検索入力ワード集計 | C97: 100000
A98: フォーム集計 | C98: 100000
A99: 自動翻訳サービス連携 | C99: 100000
A100: HTMLパブリッシュ
A101: リンクチェッカー | C101: 100000
...

Sheet 単位マスタ
A1: input_screen_label | B1: unit_type_db_value
A2: 人月 | B2: person_month
A3: 人日 | B3: person_day
A4: 式 | B4: set
A5: 頁 | B5: page
A6: 回 | B6: times
A7: % | B7: percent
A8: 月額 | B8: monthly_fee
A9: 年額 | B9: annual_fee
